Workbook

Sheet Td_Diferencias
A4: Observaciones | B4: Briyan | C4: Cesar | D4: Jesus | E4: Total general
A5: 1. No está cargado en el SICS-Tablero | C5: 1 | D5: 4 | E5: 5
A6: 2. Actualizar la vigencia en el SICS | B6: 7 | C6: 5 | D6: 7 | E6: 19
A7: 6. Revisar renovación | C7: 2 | D7: 2 | E7: 4
A8: Total general | B8: 7 | C8: 8 | D8: 13 | E8: 28

Sheet Reporte
A1: rimac | B1: rimac | C1: SICS | D1: Tablero | G1: rimac | H1: rimac
A2: RESPONSABLE DE PAGO | B2: NRO. POLIZA | C2: SICS | D2: Tablero | E2: Observaciones | F2: Responsable | G2: CATEGORÍA | H2: VENCIMIENTO | I2: MOTIVO | J2: ASEGURADORA RENOVADA | K2: POLIZANUEVA | L2: OBSERVACIONES | M2: Obs | N2: SICS
A3: FITESA PERU S.A.C. | B3: 42982 | C3: =_xlfn.XLOOKUP(B3,[1]ReportePolizaPorFiltroArribas!$G$1:$G$3955,[1]ReportePolizaPorFiltroArribas!$O$1:$O$3955,"No Encontrado",0) -> No Encontrado | D3: =_xlfn.XLOOKUP(B3,[2]Tablero!$AP$1:$AP$6608,[2]Tablero!$AE$1:$AE$6608,"No Encontrado",0) -> No Encontrado | E3: 1. No está cargado en el SICS-Tablero | F3: =IF(E3<>"",_xlfn.XLOOKUP(G3,pivot!$B$1:$B$34,pivot!$A$1:$A$34,"",0),"") -> Jesus | G3: FORMACION LABORAL | H3: 2025-10-31 | M3: =IF(C3<=TEXT(H3,"YYYY-MM"),2,6) -> 6
A4: BALTAZAR Y NICOLAS ASOCIACIÓN CIVIL SIN FINES DE LUCRO | B4: 1300649048 | C4: =_xlfn.XLOOKUP(B4,[1]ReportePolizaPorFiltroArribas!$G$1:$G$3955,[1]ReportePolizaPorFiltroArribas!$O$1:$O$3955,"No Encontrado",0) -> No Encontrado | D4: =_xlfn.XLOOKUP(B4,[2]Tablero!$AP$1:$AP$6608,[2]Tablero!$AE$1:$AE$6608,"No Encontrado",0) -> No Encontrado | E4: 1. No está cargado en el SICS-Tablero | F4: =IF(E4<>"",_xlfn.XLOOKUP(G4,pivot!$B$1:$B$34,pivot!$A$1:$A$34,"",0),"") -> Jesus | G4: VIDALEYRE | H4: 2025-11-10 | M4: =IF(C4<=TEXT(H4,"YYYY-MM"),2,6) -> 6
A5: TELECYL PERU SAC | B5: 1300649031 | C5: =_xlfn.XLOOKUP(B5,[1]ReportePolizaPorFiltroArribas!$G$1:$G$3955,[1]ReportePolizaPorFiltroArribas!$O$1:$O$3955,"No Encontrado",0) -> No Encontrado | D5: =_xlfn.XLOOKUP(B5,[2]Tablero!$AP$1:$AP$6608,[2]Tablero!$AE$1:$AE$6608,"No Encontrado",0) -> No Encontrado | E5: 1. No está cargado en el SICS-Tablero | F5: =IF(E5<>"",_xlfn.XLOOKUP(G5,pivot!$B$1:$B$34,pivot!$A$1:$A$34,"",0),"") -> Jesus | G5: VIDALEYRE | H5: 2025-11-13 | M5: =IF(C5<=TEXT(H5,"YYYY-MM"),2,6) -> 6
A6: ELECNOR PERU S.A.C. | B6: 1300047326 | C6: =_xlfn.XLOOKUP(B6,[1]ReportePolizaPorFiltroArribas!$G$1:$G$3955,[1]ReportePolizaPorFiltroArribas!$O$1:$O$3955,"No Encontrado",0) -> No Encontrado | D6: =_xlfn.XLOOKUP(B6,[2]Tablero!$AP$1:$AP$6608,[2]Tablero!$AE$1:$AE$6608,"No Encontrado",0) -> No Encontrado | E6: 1. No está cargado en el SICS-Tablero | F6: =IF(E6<>"",_xlfn.XLOOKUP(G6,pivot!$B$1:$B$34,pivot!$A$1:$A$34,"",0),"") -> Jesus | G6: VIDA LEY D.L. 688 | H6: 2025-11-13 | M6: =IF(C6<=TEXT(H6,"YYYY-MM"),2,6) -> 6
A7: LININGS S.A. | B7: 1578645 | C7: =_xlfn.XLOOKUP(B7,[1]ReportePolizaPorFiltroArribas!$G$1:$G$3955,[1]ReportePolizaPorFiltroArribas!$O$1:$O$3955,"No Encontrado",0) -> No Encontrado | D7: =_xlfn.XLOOKUP(B7,[2]Tablero!$AP$1:$AP$6608,[2]Tablero!$AE$1:$AE$6608,"No Encontrado",0) -> No Encontrado | E7: 1. No está cargado en el SICS-Tablero | F7: =IF(E7<>"",_xlfn.XLOOKUP(G7,pivot!$B$1:$B$34,pivot!$A$1:$A$34,"",0),"") -> Cesar | G7: WEB VEHICULOS | H7: 2025-11-24 | M7: =IF(C7<=TEXT(H7,"YYYY-MM"),2,6) -> 6
A8: INTERNATIONAL 4PL CARGO S.A.C. | B8: 1300369041 | C8: =_xlfn.XLOOKUP(B8,[1]ReportePolizaPorFiltroArribas!$G$1:$G$3955,[1]ReportePolizaPorFiltroArribas!$O$1:$O$3955,"No Encontrado",0) -> 2025-09 | D8: =_xlfn.XLOOKUP(B8,[2]Tablero!$AP$1:$AP$6608,[2]Tablero!$AE$1:$AE$6608,"No Encontrado",0) -> 02 - EN PROCESO | E8: 2. Actualizar la vigencia en el SICS | F8: =IF(E8<>"",_xlfn.XLOOKUP(G8,pivot!$B$1:$B$34,pivot!$A$1:$A$34,"",0),"") -> Jesus | G8: VIDA LEY D.L. 688 | H8: 2025-09-05 | M8: =IF(C8<=TEXT(H8,"YYYY-MM"),2,6) -> 2
A9: SENCINET LATAM PERU S.A.C. | B9: 1300356735 | C9: =_xlfn.XLOOKUP(B9,[1]ReportePolizaPorFiltroArribas!$G$1:$G$3955,[1]ReportePolizaPorFiltroArribas!$O$1:$O$3955,"No Encontrado",0) -> 2025-10 | D9: =_xlfn.XLOOKUP(B9,[2]Tablero!$AP$1:$AP$6608,[2]Tablero!$AE$1:$AE$6608,"No Encontrado",0) -> 01 - RENOVADA | E9: 2. Actualizar la vigencia en el SICS | F9: =IF(E9<>"",_xlfn.XLOOKUP(G9,pivot!$B$1:$B$34,pivot!$A$1:$A$34,"",0),"") -> Jesus | G9: VIDA LEY D.L. 688 | H9: 2025-10-01 | M9: =IF(C9<=TEXT(H9,"YYYY-MM"),2,6) -> 2
A10: BYBLUE PERU SOCIEDAD ANONIMA CERRADA - BYBLUE PERU S.A.C. | B10: 1300615764 | C10: =_xlfn.XLOOKUP(B10,[1]ReportePolizaPorFiltroArribas!$G$1:$G$3955,[1]ReportePolizaPorFiltroArribas!$O$1:$O$3955,"No Encontrado",0) -> 2025-10 | D10: =_xlfn.XLOOKUP(B10,[2]Tablero!$AP$1:$AP$6608,[2]Tablero!$AE$1:$AE$6608,"No Encontrado",0) -> 01 - RENOVADA | E10: 2. Actualizar la vigencia en el SICS | F10: =IF(E10<>"",_xlfn.XLOOKUP(G10,pivot!$B$1:$B$34,pivot!$A$1:$A$34,"",0),"") -> Jesus | G10: VIDA LEY D.L. 688 | H10: 2025-10-10 | M10: =IF(C10<=TEXT(H10,"YYYY-MM"),2,6) -> 2
A11: TELECYL PERU SAC | B11: 65598970 | C11: =_xlfn.XLOOKUP(B11,[1]ReportePolizaPorFiltroArribas!$G$1:$G$3955,[1]ReportePolizaPorFiltroArribas!$O$1:$O$3955,"No Encontrado",0) -> 2025-10 | D11: =_xlfn.XLOOKUP(B11,[2]Tablero!$AP$1:$AP$6608,[2]Tablero!$AE$1:$AE$6608,"No Encontrado",0) -> 03 - PENDIENTE | E11: 2. Actualizar la vigencia en el SICS | F11: =IF(E11<>"",_xlfn.XLOOKUP(G11,pivot!$B$1:$B$34,pivot!$A$1:$A$34,"",0),"") -> Jesus | G11: VIDA LEY D.L. 688 | H11: 2025-10-10 | M11: =IF(C11<=TEXT(H11,"YYYY-MM"),2,6) -> 2
A12: LABORATORIO FARMACEUTICO SAN JOAQUIN-ROXFARMA SOCIEDAD ANONIMA | B12: 44654 | C12: =_xlfn.XLOOKUP(B12,[1]ReportePolizaPorFiltroArribas!$G$1:$G$3955,[1]ReportePolizaPorFiltroArribas!$O$1:$O$3955,"No Encontrado",0) -> 2025-10 | D12: =_xlfn.XLOOKUP(B12,[2]Tablero!$AP$1:$AP$6608,[2]Tablero!$AE$1:$AE$6608,"No Encontrado",0) -> 03 - PENDIENTE | E12: 2. Actualizar la vigencia en el SICS | F12: =IF(E12<>"",_xlfn.XLOOKUP(G12,pivot!$B$1:$B$34,pivot!$A$1:$A$34,"",0),"") -> Jesus | G12: FORMACION LABORAL | H12: 2025-10-17 | M12: =IF(C12<=TEXT(H12,"YYYY-MM"),2,6) -> 2
A13: GILES PONCE CARLOS LEONIDAS | B13: 74840 | C13: =_xlfn.XLOOKUP(B13,[1]ReportePolizaPorFiltroArribas!$G$1:$G$3955,[1]ReportePolizaPorFiltroArribas!$O$1:$O$3955,"No Encontrado",0) -> 2025-11 | D13: =_xlfn.XLOOKUP(B13,[2]Tablero!$AP$1:$AP$6608,[2]Tablero!$AE$1:$AE$6608,"No Encontrado",0) -> 03 - PENDIENTE | E13: 2. Actualizar la vigencia en el SICS | F13: =IF(E13<>"",_xlfn.XLOOKUP(G13,pivot!$B$1:$B$34,pivot!$A$1:$A$34,"",0),"") -> Briyan | G13: SALUD RED MÉDICA | H13: 2025-11-04 | M13: =IF(C13<=TEXT(H13,"YYYY-MM"),2,6) -> 2
A14: FLOR TORO JOSE LUIS | B14: 456784 | C14: =_xlfn.XLOOKUP(B14,[1]ReportePolizaPorFiltroArribas!$G$1:$G$3955,[1]ReportePolizaPorFiltroArribas!$O$1:$O$3955,"No Encontrado",0) -> 2025-11 | D14: =_xlfn.XLOOKUP(B14,[2]Tablero!$AP$1:$AP$6608,[2]Tablero!$AE$1:$AE$6608,"No Encontrado",0) -> 01 - RENOVADA | E14: 2. Actualizar la vigencia en el SICS | F14: =IF(E14<>"",_xlfn.XLOOKUP(G14,pivot!$B$1:$B$34,pivot!$A$1:$A$34,"",0),"") -> Cesar | G14: WEB VEHICULOS | H14: 2025-11-15 | M14: =IF(C14<=TEXT(H14,"YYYY-MM"),2,6) -> 2
... A24: BPZ EXPLORACION & PRODUCCION S.R.L. | B24: 53662 | C24: =_xlfn.XLOOKUP(B24,[1]ReportePolizaPorFiltroArribas!$G$1:$G$3955,[1]ReportePolizaPorFiltroArribas!$O$1:$O$3955,"No Encontrado",0) -> 2025-11 | D24: =_xlfn.XLOOKUP(B24,[2]Tablero!$AP$1:$AP$6608,[2]Tablero!$AE$1:$AE$6608,"No Encontrado",0) -> 03 - PENDIENTE | E24: 2. Actualizar la vigencia en el SICS | F24: =IF(E24<>"",_xlfn.XLOOKUP(G24,pivot!$B$1:$B$34,pivot!$A$1:$A$34,"",0),"") -> Briyan | G24: FULLSALUD | H24: 2025-12-31 | M24: =IF(C24<=TEXT(H24,"YYYY-MM"),2,6) -> 2
A25: IMPRESSO GRAFICA S A | B25: E0001323 | C25: =_xlfn.XLOOKUP(B25,[1]ReportePolizaPorFiltroArribas!$G$1:$G$3955,[1]ReportePolizaPorFiltroArribas!$O$1:$O$3955,"No Encontrado",0) -> 2025-10 | D25: =_xlfn.XLOOKUP(B25,[2]Tablero!$AP$1:$AP$6608,[2]Tablero!$AE$1:$AE$6608,"No Encontrado",0) -> No Encontrado | E25: 2. Actualizar la vigencia en el SICS | F25: =IF(E25<>"",_xlfn.XLOOKUP(G25,pivot!$B$1:$B$34,pivot!$A$1:$A$34,"",0),"") -> Briyan | G25: EPS | H25: 2025-11-03 | M25: =IF(C25<=TEXT(H25,"YYYY-MM"),2,6) -> 2
A26: LININGS S.A. | B26: 1581063 | C26: =_xlfn.XLOOKUP(B26,[1]ReportePolizaPorFiltroArribas!$G$1:$G$3955,[1]ReportePolizaPorFiltroArribas!$O$1:$O$3955,"No Encontrado",0) -> 2025-10 | D26: =_xlfn.XLOOKUP(B26,[2]Tablero!$AP$1:$AP$6608,[2]Tablero!$AE$1:$AE$6608,"No Encontrado",0) -> 01 - RENOVADA | E26: 2. Actualizar la vigencia en el SICS | F26: =IF(E26<>"",_xlfn.XLOOKUP(G26,pivot!$B$1:$B$34,pivot!$A$1:$A$34,"",0),"") -> Cesar | G26: WEB VEHICULOS | H26: 2025-11-24 | M26: =IF(C26<=TEXT(H26,"YYYY-MM"),2,6) -> 2
A27: SEMINARIO Y CIA S.A.B. S. A. | B27: 44936720 | C27: =_xlfn.XLOOKUP(B27,[1]ReportePolizaPorFiltroArribas!$G$1:$G$3955,[1]ReportePolizaPorFiltroArribas!$O$1:$O$3955,"No Encontrado",0) -> 2025-10 | D27: =_xlfn.XLOOKUP(B27,[2]Tablero!$AP$1:$AP$6608,[2]Tablero!$AE$1:$AE$6608,"No Encontrado",0) -> 03 - PENDIENTE | E27: 6. Revisar renovación | F27: =IF(E27<>"",_xlfn.XLOOKUP(G27,pivot!$B$1:$B$34,pivot!$A$1:$A$34,"",0),"") -> Jesus | G27: VIDA LEY D.L. 688 | H27: 2025-07-11 | M27: =IF(C27<=TEXT(H27,"YYYY-MM"),2,6) -> 6
A28: XIAOMI TECHNOLOGIES PERU S.A.C. | B28: 48411 | C28: =_xlfn.XLOOKUP(B28,[1]ReportePolizaPorFiltroArribas!$G$1:$G$3955,[1]ReportePolizaPorFiltroArribas!$O$1:$O$3955,"No Encontrado",0) -> 2025-10 | D28: =_xlfn.XLOOKUP(B28,[2]Tablero!$AP$1:$AP$6608,[2]Tablero!$AE$1:$AE$6608,"No Encontrado",0) -> 03 - PENDIENTE | E28: 6. Revisar renovación | F28: =IF(E28<>"",_xlfn.XLOOKUP(G28,pivot!$B$1:$B$34,pivot!$A$1:$A$34,"",0),"") -> Jesus | G28: FORMACION LABORAL | H28: 2025-09-25 | M28: =IF(C28<=TEXT(H28,"YYYY-MM"),2,6) -> 6
A29: URRUTIA NUÑEZ PAOLA PILAR | B29: 1469526 | C29: =_xlfn.XLOOKUP(B29,[1]ReportePolizaPorFiltroArribas!$G$1:$G$3955,[1]ReportePolizaPorFiltroArribas!$O$1:$O$3955,"No Encontrado",0) -> 2025-11 | D29: =_xlfn.XLOOKUP(B29,[2]Tablero!$AP$1:$AP$6608,[2]Tablero!$AE$1:$AE$6608,"No Encontrado",0) -> No Encontrado | E29: 6. Revisar renovación | F29: =IF(E29<>"",_xlfn.XLOOKUP(G29,pivot!$B$1:$B$34,pivot!$A$1:$A$34,"",0),"") -> Cesar | G29: WEB VEHICULOS | H29: 2025-09-18 | M29: =IF(C29<=TEXT(H29,"YYYY-MM"),2,6) -> 6
A30: ISLA HERRERA HARRY | B30: 1469534 | C30: =_xlfn.XLOOKUP(B30,[1]ReportePolizaPorFiltroArribas!$G$1:$G$3955,[1]ReportePolizaPorFiltroArribas!$O$1:$O$3955,"No Encontrado",0) -> 2025-11 | D30: =_xlfn.XLOOKUP(B30,[2]Tablero!$AP$1:$AP$6608,[2]Tablero!$AE$1:$AE$6608,"No Encontrado",0) -> 03 - PENDIENTE | E30: 6. Revisar renovación | F30: =IF(E30<>"",_xlfn.XLOOKUP(G30,pivot!$B$1:$B$34,pivot!$A$1:$A$34,"",0),"") -> Cesar | G30: WEB VEHICULOS | H30: 2025-10-11 | M30: =IF(C30<=TEXT(H30,"YYYY-MM"),2,6) -> 6
A31: AGUAS DE BAYOVAR S.A.C. | B31: 251980 | C31: =_xlfn.XLOOKUP(B31,[1]ReportePolizaPorFiltroArribas!$G$1:$G$3955,[1]ReportePolizaPorFiltroArribas!$O$1:$O$3955,"No Encontrado",0) -> 2025-11 | D31: =_xlfn.XLOOKUP(B31,[2]Tablero!$AP$1:$AP$6608,[2]Tablero!$AE$1:$AE$6608,"No Encontrado",0) -> 01 - RENOVADA | F31: =IF(E31<>"",_xlfn.XLOOKUP(G31,pivot!$B$1:$B$34,pivot!$A$1:$A$34,"",0),"") | G31: VIDA LEY D.L. 688 | H31: 2025-11-01 | M31: =IF(C31<=TEXT(H31,"YYYY-MM"),2,6) -> 2
A32: TALLERES LA LEGUA SOCIEDAD ANONIMA CERRADA - TALLERES LA LEGUA S.A.C. | B32: 93965515 | C32: =_xlfn.XLOOKUP(B32,[1]ReportePolizaPorFiltroArribas!$G$1:$G$3955,[1]ReportePolizaPorFiltroArribas!$O$1:$O$3955,"No Encontrado",0) -> 2025-11 | D32: =_xlfn.XLOOKUP(B32,[2]Tablero!$AP$1:$AP$6608,[2]Tablero!$AE$1:$AE$6608,"No Encontrado",0) -> 03 - PENDIENTE | F32: =IF(E32<>"",_xlfn.XLOOKUP(G32,pivot!$B$1:$B$34,pivot!$A$1:$A$34,"",0),"") | G32: VIDA LEY D.L. 688 | H32: 2025-11-01 | M32: =IF(C32<=TEXT(H32,"YYYY-MM"),2,6) -> 2
A33: CLUB SPORTING CRISTAL S.A. | B33: E0002259 | C33: =_xlfn.XLOOKUP(B33,[1]ReportePolizaPorFiltroArribas!$G$1:$G$3955,[1]ReportePolizaPorFiltroArribas!$O$1:$O$3955,"No Encontrado",0) -> No Encontrado | D33: =_xlfn.XLOOKUP(B33,[2]Tablero!$AP$1:$AP$6608,[2]Tablero!$AE$1:$AE$6608,"No Encontrado",0) -> 05 - ANULADA EN VIGENCIA | F33: =IF(E33<>"",_xlfn.XLOOKUP(G33,pivot!$B$1:$B$34,pivot!$A$1:$A$34,"",0),"") | G33: EPS | H33: 2023-05-29 | M33: =IF(C33<=TEXT(H33,"YYYY-MM"),2,6) -> 6
A34: CAMPARI PERU SOCIEDAD ANONIMA CERRADA - CAMPARI PERU S.A.C. | B34: E0029631 | C34: =_xlfn.XLOOKUP(B34,[1]ReportePolizaPorFiltroArribas!$G$1:$G$3955,[1]ReportePolizaPorFiltroArribas!$O$1:$O$3955,"No Encontrado",0) -> No Encontrado | D34: =_xlfn.XLOOKUP(B34,[2]Tablero!$AP$1:$AP$6608,[2]Tablero!$AE$1:$AE$6608,"No Encontrado",0) -> 04 - NO RENOVADA | F34: =IF(E34<>"",_xlfn.XLOOKUP(G34,pivot!$B$1:$B$34,pivot!$A$1:$A$34,"",0),"") | G34: EPS | H34: 2023-10-02 | M34: =IF(C34<=TEXT(H34,"YYYY-MM"),2,6) -> 6
A35: CIMER INGENIEROS SAC | B35: S0350529 | C35: =_xlfn.XLOOKUP(B35,[1]ReportePolizaPorFiltroArribas!$G$1:$G$3955,[1]ReportePolizaPorFiltroArribas!$O$1:$O$3955,"No Encontrado",0) -> No Encontrado | D35: =_xlfn.XLOOKUP(B35,[2]Tablero!$AP$1:$AP$6608,[2]Tablero!$AE$1:$AE$6608,"No Encontrado",0) -> 04 - NO RENOVADA | F35: =IF(E35<>"",_xlfn.XLOOKUP(G35,pivot!$B$1:$B$34,pivot!$A$1:$A$34,"",0),"") | G35: S.C.T.R. - SALUD | H35: 2024-12-02 | M35: =IF(C35<=TEXT(H35,"YYYY-MM"),2,6) -> 6
A36: DIGITAL BUSINESS PERU S.A.C. | B36: E0004449 | C36: =_xlfn.XLOOKUP(B36,[1]ReportePolizaPorFiltroArribas!$G$1:$G$3955,[1]ReportePolizaPorFiltroArribas!$O$1:$O$3955,"No Encontrado",0) -> No Encontrado | D36: =_xlfn.XLOOKUP(B36,[2]Tablero!$AP$1:$AP$6608,[2]Tablero!$AE$1:$AE$6608,"No Encontrado",0) -> 05 - ANULADA EN VIGENCIA | F36: =IF(E36<>"",_xlfn.XLOOKUP(G36,pivot!$B$1:$B$34,pivot!$A$1:$A$34,"",0),"") | G36: EPS | H36: 2025-02-03 | M36: =IF(C36<=TEXT(H36,"YYYY-MM"),2,6) -> 6
A37: BELTRAN BYRNE GUILLERMO | B37: E0027232 | C37: =_xlfn.XLOOKUP(B37,[1]ReportePolizaPorFiltroArribas!$G$1:$G$3955,[1]ReportePolizaPorFiltroArribas!$O$1:$O$3955,"No Encontrado",0) -> No Encontrado | D37: =_xlfn.XLOOKUP(B37,[2]Tablero!$AP$1:$AP$6608,[2]Tablero!$AE$1:$AE$6608,"No Encontrado",0) -> 05 - ANULADA EN VIGENCIA | F37: =IF(E37<>"",_xlfn.XLOOKUP(G37,pivot!$B$1:$B$34,pivot!$A$1:$A$34,"",0),"") | G37: EPS | H37: 2025-05-07 | M37: =IF(C37<=TEXT(H37,"YYYY-MM"),2,6) -> 6
A38: CONTRERAS IVARCENA EDUARDO DIEGO | B38: 1483595 | C38: =_xlfn.XLOOKUP(B38,[1]ReportePolizaPorFiltroArribas!$G$1:$G$3955,[1]ReportePolizaPorFiltroArribas!$O$1:$O$3955,"No Encontrado",0) -> 2026-01 | D38: =_xlfn.XLOOKUP(B38,[2]Tablero!$AP$1:$AP$6608,[2]Tablero!$AE$1:$AE$6608,"No Encontrado",0) -> 01 - RENOVADA | F38: =IF(E38<>"",_xlfn.XLOOKUP(G38,pivot!$B$1:$B$34,pivot!$A$1:$A$34,"",0),"") | G38: WEB VEHICULOS | H38: 2025-05-28 | M38: =IF(C38<=TEXT(H38,"YYYY-MM"),2,6) -> 6
A39: BRAVO GARCIA BELEN SARAI | B39: 67765 | C39: =_xlfn.XLOOKUP(B39,[1]ReportePolizaPorFiltroArribas!$G$1:$G$3955,[1]ReportePolizaPorFiltroArribas!$O$1:$O$3955,"No Encontrado",0) -> 2026-01 | D39: =_xlfn.XLOOKUP(B39,[2]Tablero!$AP$1:$AP$6608,[2]Tablero!$AE$1:$AE$6608,"No Encontrado",0) -> 01 - RENOVADA | F39: =IF(E39<>"",_xlfn.XLOOKUP(G39,pivot!$B$1:$B$34,pivot!$A$1:$A$34,"",0),"") | G39: SALUD RED PREFERENTE | H39: 2025-07-28 | M39: =IF(C39<=TEXT(H39,"YYYY-MM"),2,6) -> 6
A40: INMOBILIARIA EGP S.A.C. | B40: 1544218 | C40: =_xlfn.XLOOKUP(B40,[1]ReportePolizaPorFiltroArribas!$G$1:$G$3955,[1]ReportePolizaPorFiltroArribas!$O$1:$O$3955,"No Encontrado",0) -> 2026-04 | D40: =_xlfn.XLOOKUP(B40,[2]Tablero!$AP$1:$AP$6608,[2]Tablero!$AE$1:$AE$6608,"No Encontrado",0) -> 01 - RENOVADA | F40: =IF(E40<>"",_xlfn.XLOOKUP(G40,pivot!$B$1:$B$34,pivot!$A$1:$A$34,"",0),"") | G40: WEB VEHICULOS | H40: 2025-07-29 | M40: =IF(C40<=TEXT(H40,"YYYY-MM"),2,6) -> 6
A41: TEGA INDUSTRIES PERU S.A.C. | B41: 48599 | C41: =_xlfn.XLOOKUP(B41,[1]ReportePolizaPorFiltroArribas!$G$1:$G$3955,[1]ReportePolizaPorFiltroArribas!$O$1:$O$3955,"No Encontrado",0) -> 2026-03 | D41: =_xlfn.XLOOKUP(B41,[2]Tablero!$AP$1:$AP$6608,[2]Tablero!$AE$1:$AE$6608,"No Encontrado",0) -> 03 - PENDIENTE | F41: =IF(E41<>"",_xlfn.XLOOKUP(G41,pivot!$B$1:$B$34,pivot!$A$1:$A$34,"",0),"") | G41: FORMACION LABORAL | H41: 2025-07-31 | M41: =IF(C41<=TEXT(H41,"YYYY-MM"),2,6) -> 6
A42: DIGITAL BUSINESS PERU S.A.C. | B42: 67289811 | C42: =_xlfn.XLOOKUP(B42,[1]ReportePolizaPorFiltroArribas!$G$1:$G$3955,[1]ReportePolizaPorFiltroArribas!$O$1:$O$3955,"No Encontrado",0) -> 2026-03 | D42: =_xlfn.XLOOKUP(B42,[2]Tablero!$AP$1:$AP$6608,[2]Tablero!$AE$1:$AE$6608,"No Encontrado",0) -> 05 - ANULADA EN VIGENCIA | F42: =IF(E42<>"",_xlfn.XLOOKUP(G42,pivot!$B$1:$B$34,pivot!$A$1:$A$34,"",0),"") | G42: VIDA LEY D.L. 688 | H42: 2025-08-01 | M42: =IF(C42<=TEXT(H42,"YYYY-MM"),2,6) -> 6
A43: VARAS RUIZ LUCIA MIREILLE | B43: E0035204 | C43: =_xlfn.XLOOKUP(B43,[1]ReportePolizaPorFiltroArribas!$G$1:$G$3955,[1]ReportePolizaPorFiltroArribas!$O$1:$O$3955,"No Encontrado",0) -> No Encontrado | D43: =_xlfn.XLOOKUP(B43,[2]Tablero!$AP$1:$AP$6608,[2]Tablero!$AE$1:$AE$6608,"No Encontrado",0) -> 04 - NO RENOVADA | F43: =IF(E43<>"",_xlfn.XLOOKUP(G43,pivot!$B$1:$B$34,pivot!$A$1:$A$34,"",0),"") | G43: EPS | H43: 2025-08-14 | M43: =IF(C43<=TEXT(H43,"YYYY-MM"),2,6) -> 6
A44: DIGITAL VENTURES S.A.C. | B44: 1300364536 | C44: =_xlfn.XLOOKUP(B44,[1]ReportePolizaPorFiltroArribas!$G$1:$G$3955,[1]ReportePolizaPorFiltroArribas!$O$1:$O$3955,"No Encontrado",0) -> 2025-12 | D44: =_xlfn.XLOOKUP(B44,[2]Tablero!$AP$1:$AP$6608,[2]Tablero!$AE$1:$AE$6608,"No Encontrado",0) -> 01 - RENOVADA | F44: =IF(E44<>"",_xlfn.XLOOKUP(G44,pivot!$B$1:$B$34,pivot!$A$1:$A$34,"",0),"") | G44: VIDA LEY D.L. 688 | H44: 2025-08-23 | M44: =IF(C44<=TEXT(H44,"YYYY-MM"),2,6) -> 6
A45: GONZALES SALAZAR JUAN MANUEL | B45: 1443523 | C45: =_xlfn.XLOOKUP(B45,[1]ReportePolizaPorFiltroArribas!$G$1:$G$3955,[1]ReportePolizaPorFiltroArribas!$O$1:$O$3955,"No Encontrado",0) -> 2026-07 | D45: =_xlfn.XLOOKUP(B45,[2]Tablero!$AP$1:$AP$6608,[2]Tablero!$AE$1:$AE$6608,"No Encontrado",0) -> 01 - RENOVADA | F45: =IF(E45<>"",_xlfn.XLOOKUP(G45,pivot!$B$1:$B$34,pivot!$A$1:$A$34,"",0),"") | G45: WEB VEHICULOS | H45: 2025-08-25 | M45: =IF(C45<=TEXT(H45,"YYYY-MM"),2,6) -> 6
A46: GESTION A1 S.A.C. - GA1 S.A.C. | B46: E0033183 | C46: =_xlfn.XLOOKUP(B46,[1]ReportePolizaPorFiltroArribas!$G$1:$G$3955,[1]ReportePolizaPorFiltroArribas!$O$1:$O$3955,"No Encontrado",0) -> 2025-12 | D46: =_xlfn.XLOOKUP(B46,[2]Tablero!$AP$1:$AP$6608,[2]Tablero!$AE$1:$AE$6608,"No Encontrado",0) -> 03 - PENDIENTE | F46: =IF(E46<>"",_xlfn.XLOOKUP(G46,pivot!$B$1:$B$34,pivot!$A$1:$A$34,"",0),"") | G46: EPS | H46: 2025-09-01 | M46: =IF(C46<=TEXT(H46,"YYYY-MM"),2,6) -> 6
A47: XIAOMI TECHNOLOGIES PERU S.A.C. | B47: 54590 | C47: =_xlfn.XLOOKUP(B47,[1]ReportePolizaPorFiltroArribas!$G$1:$G$3955,[1]ReportePolizaPorFiltroArribas!$O$1:$O$3955,"No Encontrado",0) -> 2026-09 | D47: =_xlfn.XLOOKUP(B47,[2]Tablero!$AP$1:$AP$6608,[2]Tablero!$AE$1:$AE$6608,"No Encontrado",0) -> 03 - PENDIENTE | F47: =IF(E47<>"",_xlfn.XLOOKUP(G47,pivot!$B$1:$B$34,pivot!$A$1:$A$34,"",0),"") | G47: FULLSALUD | H47: 2025-09-04 | M47: =IF(C47<=TEXT(H47,"YYYY-MM"),2,6) -> 6
A48: XIAOMI RETAIL PERU S.A.C. | B48: 54605 | C48: =_xlfn.XLOOKUP(B48,[1]ReportePolizaPorFiltroArribas!$G$1:$G$3955,[1]ReportePolizaPorFiltroArribas!$O$1:$O$3955,"No Encontrado",0) -> 2026-09 | D48: =_xlfn.XLOOKUP(B48,[2]Tablero!$AP$1:$AP$6608,[2]Tablero!$AE$1:$AE$6608,"No Encontrado",0) -> 03 - PENDIENTE | F48: =IF(E48<>"",_xlfn.XLOOKUP(G48,pivot!$B$1:$B$34,pivot!$A$1:$A$34,"",0),"") | G48: FULLSALUD | H48: 2025-09-04 | M48: =IF(C48<=TEXT(H48,"YYYY-MM"),2,6) -> 6
A49: VALEI PRODUCCIONES E.I.R.L | B49: 69523 | C49: =_xlfn.XLOOKUP(B49,[1]ReportePolizaPorFiltroArribas!$G$1:$G$3955,[1]ReportePolizaPorFiltroArribas!$O$1:$O$3955,"No Encontrado",0) -> 2026-02 | D49: =_xlfn.XLOOKUP(B49,[2]Tablero!$AP$1:$AP$6608,[2]Tablero!$AE$1:$AE$6608,"No Encontrado",0) -> 01 - RENOVADA | F49: =IF(E49<>"",_xlfn.XLOOKUP(G49,pivot!$B$1:$B$34,pivot!$A$1:$A$34,"",0),"") | G49: SALUD RED MÉDICA | H49: 2025-09-04 | M49: =IF(C49<=TEXT(H49,"YYYY-MM"),2,6) -> 6
...

Sheet pivot
A1: Responsable | B1: CATEGORÍA
A2: Jesus | B2: S.C.T.R. - PENSION | F2: 1. No está cargado en el SICS-Tablero
A3: Jesus | B3: VIDA LEY D.L. 688 | F3: 2. Actualizar la vigencia en el SICS | G3: SICS | H3: <= | I3: VCTO
A4: Jesus | B4: VIDALEYRE | F4: 6. Revisar renovación | G4: SICS | H4: > | I4: VCTO
A5: Briyan | B5: SALUD RED PREFERENTE
A6: Briyan | B6: SALUD RED PREFERENTE F F V V
A7: Briyan | B7: SALUD RED MEDICA F F V V
A8: Jesus | B8: S.C.T.R. - SALUD
A9: Jesus | B9: VIDA GRUPO
A10: Jesus | B10: FORMACION LABORAL
A11: Jesus | B11: VIDA LEY 2DA CAPA
A12: Jesus | B12: ONCOLÓGICO RIMAC
A13: Jesus | B13: ACCIDENTES SEGURO VIDA B
A14: Briyan | B14: SALUD DE ORO F F V V
A15: Briyan | B15: SALUD FLEXIBLE
A16: Briyan | B16: FULLSALUD
... A34: Thalia | B34: 3D
